Python 3.13.3 (tags/v3.13.3:6280bb5, Apr  8 2025, 14:47:33) [MSC v.1943 64 bit (AMD64)] on win32
Enter "help" below or click "Help" above for more information.

=========== RESTART: C:/Users/LENOVO/Desktop/PYTHON FINAL PROJECT.py ===========
    Ride ID Request Time  ... Canceled By Customer Rating
0  79efd31e      43:27.9  ...      Driver             0.0
1  75ee4cc8      27:27.9  ...      Driver             0.0
2  4bc4129c      11:27.9  ...         NaN             3.6
3  c8cacb82      46:27.9  ...         NaN             1.0
4  0bcf3f46      02:27.9  ...         NaN             1.5

[5 rows x 21 columns]

=========== RESTART: C:/Users/LENOVO/Desktop/PYTHON FINAL PROJECT.py ===========
    Ride ID Request Time  ... Canceled By Customer Rating
0  79efd31e      43:27.9  ...      Driver             0.0
1  75ee4cc8      27:27.9  ...      Driver             0.0
2  4bc4129c      11:27.9  ...         NaN             3.6
3  c8cacb82      46:27.9  ...         NaN             1.0
4  0bcf3f46      02:27.9  ...         NaN             1.5

[5 rows x 21 columns]

=========== RESTART: C:/Users/LENOVO/Desktop/PYTHON FINAL PROJECT.py ===========
    Ride ID Request Time  ... Canceled By Customer Rating
0  79efd31e      43:27.9  ...      Driver             0.0
1  75ee4cc8      27:27.9  ...      Driver             0.0
2  4bc4129c      11:27.9  ...         NaN             3.6
3  c8cacb82      46:27.9  ...         NaN             1.0
4  0bcf3f46      02:27.9  ...         NaN             1.5

[5 rows x 21 columns]

=========== RESTART: C:/Users/LENOVO/Desktop/PYTHON FINAL PROJECT.py ===========
    Ride ID Request Time  ... Canceled By Customer Rating
0  79efd31e      43:27.9  ...      Driver             0.0
1  75ee4cc8      27:27.9  ...      Driver             0.0
2  4bc4129c      11:27.9  ...         NaN             3.6
3  c8cacb82      46:27.9  ...         NaN             1.0
4  0bcf3f46      02:27.9  ...         NaN             1.5

[5 rows x 21 columns]

=========== RESTART: C:/Users/LENOVO/Desktop/PYTHON FINAL PROJECT.py ===========
    Ride ID Request Time  ... Canceled By Customer Rating
0  79efd31e      43:27.9  ...      Driver             0.0
1  75ee4cc8      27:27.9  ...      Driver             0.0
2  4bc4129c      11:27.9  ...         NaN             3.6
3  c8cacb82      46:27.9  ...         NaN             1.0
4  0bcf3f46      02:27.9  ...         NaN             1.5

[5 rows x 21 columns]

=========== RESTART: C:/Users/LENOVO/Desktop/PYTHON FINAL PROJECT.py ===========
    Ride ID Request Time  ... Canceled By Customer Rating
0  79efd31e      43:27.9  ...      Driver             0.0
1  75ee4cc8      27:27.9  ...      Driver             0.0
2  4bc4129c      11:27.9  ...         NaN             3.6
3  c8cacb82      46:27.9  ...         NaN             1.0
4  0bcf3f46      02:27.9  ...         NaN             1.5

[5 rows x 21 columns]
Traceback (most recent call last):
  File "C:/Users/LENOVO/Desktop/PYTHON FINAL PROJECT.py", line 39, in <module>
    plot.bar(traffic_time['Traffic Condition'], traffic_time['Actual Time (mins)'], color='red')
NameError: name 'traffic_time' is not defined

=========== RESTART: C:/Users/LENOVO/Desktop/PYTHON FINAL PROJECT.py ===========
    Ride ID Request Time  ... Canceled By Customer Rating
0  79efd31e      43:27.9  ...      Driver             0.0
1  75ee4cc8      27:27.9  ...      Driver             0.0
2  4bc4129c      11:27.9  ...         NaN             3.6
3  c8cacb82      46:27.9  ...         NaN             1.0
4  0bcf3f46      02:27.9  ...         NaN             1.5

[5 rows x 21 columns]
Traceback (most recent call last):
  File "C:/Users/LENOVO/Desktop/PYTHON FINAL PROJECT.py", line 46, in <module>
    plot.bar(traffic_fare['Traffic Condition'], traffic_fare['Actual Fare'], color='green')
NameError: name 'traffic_fare' is not defined. Did you mean: 'traffic_time'?

=========== RESTART: C:/Users/LENOVO/Desktop/PYTHON FINAL PROJECT.py ===========
    Ride ID Request Time  ... Canceled By Customer Rating
0  79efd31e      43:27.9  ...      Driver             0.0
1  75ee4cc8      27:27.9  ...      Driver             0.0
2  4bc4129c      11:27.9  ...         NaN             3.6
3  c8cacb82      46:27.9  ...         NaN             1.0
4  0bcf3f46      02:27.9  ...         NaN             1.5

[5 rows x 21 columns]
Traceback (most recent call last):
  File "C:/Users/LENOVO/Desktop/PYTHON FINAL PROJECT.py", line 46, in <module>
    plot.bar(traffic_fare['Traffic Condition'], traffic_fare['Actual Fare'], color='green')
NameError: name 'traffic_fare' is not defined. Did you mean: 'traffic_time'?

=========== RESTART: C:/Users/LENOVO/Desktop/PYTHON FINAL PROJECT.py ===========
    Ride ID Request Time  ... Canceled By Customer Rating
0  79efd31e      43:27.9  ...      Driver             0.0
1  75ee4cc8      27:27.9  ...      Driver             0.0
2  4bc4129c      11:27.9  ...         NaN             3.6
3  c8cacb82      46:27.9  ...         NaN             1.0
4  0bcf3f46      02:27.9  ...         NaN             1.5

[5 rows x 21 columns]
Traceback (most recent call last):
  File "C:\Users\LENOVO\Desktop\python1\Lib\site-packages\pandas\core\indexes\base.py", line 3805, in get_loc
    return self._engine.get_loc(casted_key)
  File "index.pyx", line 167, in pandas._libs.index.IndexEngine.get_loc
  File "index.pyx", line 196, in pandas._libs.index.IndexEngine.get_loc
  File "pandas\\_libs\\hashtable_class_helper.pxi", line 7081, in pandas._libs.hashtable.PyObjectHashTable.get_item
  File "pandas\\_libs\\hashtable_class_helper.pxi", line 7089, in pandas._libs.hashtable.PyObjectHashTable.get_item
KeyError: 0

The above exception was the direct cause of the following exception:

Traceback (most recent call last):
  File "C:/Users/LENOVO/Desktop/PYTHON FINAL PROJECT.py", line 64, in <module>
    plot.bar(failure_rate['Payment Method'], failure_rate[0], color='coral')
  File "C:\Users\LENOVO\Desktop\python1\Lib\site-packages\pandas\core\frame.py", line 4102, in __getitem__
    indexer = self.columns.get_loc(key)
  File "C:\Users\LENOVO\Desktop\python1\Lib\site-packages\pandas\core\indexes\base.py", line 3812, in get_loc
    raise KeyError(key) from err
KeyError: 0

=========== RESTART: C:/Users/LENOVO/Desktop/PYTHON FINAL PROJECT.py ===========
    Ride ID Request Time  ... Canceled By Customer Rating
0  79efd31e      43:27.9  ...      Driver             0.0
1  75ee4cc8      27:27.9  ...      Driver             0.0
2  4bc4129c      11:27.9  ...         NaN             3.6
3  c8cacb82      46:27.9  ...         NaN             1.0
4  0bcf3f46      02:27.9  ...         NaN             1.5

[5 rows x 21 columns]
Traceback (most recent call last):
  File "C:\Users\LENOVO\Desktop\python1\Lib\site-packages\pandas\core\indexes\base.py", line 3805, in get_loc
    return self._engine.get_loc(casted_key)
  File "index.pyx", line 167, in pandas._libs.index.IndexEngine.get_loc
  File "index.pyx", line 196, in pandas._libs.index.IndexEngine.get_loc
  File "pandas\\_libs\\hashtable_class_helper.pxi", line 7081, in pandas._libs.hashtable.PyObjectHashTable.get_item
  File "pandas\\_libs\\hashtable_class_helper.pxi", line 7089, in pandas._libs.hashtable.PyObjectHashTable.get_item
KeyError: 0

The above exception was the direct cause of the following exception:

Traceback (most recent call last):
  File "C:/Users/LENOVO/Desktop/PYTHON FINAL PROJECT.py", line 72, in <module>
    plot.bar(completion['Pickup Location'], completion[0], color='blue')
  File "C:\Users\LENOVO\Desktop\python1\Lib\site-packages\pandas\core\frame.py", line 4102, in __getitem__
    indexer = self.columns.get_loc(key)
  File "C:\Users\LENOVO\Desktop\python1\Lib\site-packages\pandas\core\indexes\base.py", line 3812, in get_loc
    raise KeyError(key) from err
KeyError: 0

=========== RESTART: C:/Users/LENOVO/Desktop/PYTHON FINAL PROJECT.py ===========
    Ride ID Request Time  ... Canceled By Customer Rating
0  79efd31e      43:27.9  ...      Driver             0.0
1  75ee4cc8      27:27.9  ...      Driver             0.0
2  4bc4129c      11:27.9  ...         NaN             3.6
3  c8cacb82      46:27.9  ...         NaN             1.0
4  0bcf3f46      02:27.9  ...         NaN             1.5

[5 rows x 21 columns]
Traceback (most recent call last):
  File "C:\Users\LENOVO\Desktop\python1\Lib\site-packages\pandas\core\indexes\base.py", line 3805, in get_loc
    return self._engine.get_loc(casted_key)
  File "index.pyx", line 167, in pandas._libs.index.IndexEngine.get_loc
  File "index.pyx", line 196, in pandas._libs.index.IndexEngine.get_loc
  File "pandas\\_libs\\hashtable_class_helper.pxi", line 7081, in pandas._libs.hashtable.PyObjectHashTable.get_item
  File "pandas\\_libs\\hashtable_class_helper.pxi", line 7089, in pandas._libs.hashtable.PyObjectHashTable.get_item
KeyError: 0

The above exception was the direct cause of the following exception:

Traceback (most recent call last):
  File "C:/Users/LENOVO/Desktop/PYTHON FINAL PROJECT.py", line 72, in <module>
    plot.bar(completion['Pickup Location'], completion[0], color='blue')
  File "C:\Users\LENOVO\Desktop\python1\Lib\site-packages\pandas\core\frame.py", line 4102, in __getitem__
    indexer = self.columns.get_loc(key)
  File "C:\Users\LENOVO\Desktop\python1\Lib\site-packages\pandas\core\indexes\base.py", line 3812, in get_loc
    raise KeyError(key) from err
KeyError: 0

=========== RESTART: C:/Users/LENOVO/Desktop/PYTHON FINAL PROJECT.py ===========
    Ride ID Request Time  ... Canceled By Customer Rating
0  79efd31e      43:27.9  ...      Driver             0.0
1  75ee4cc8      27:27.9  ...      Driver             0.0
2  4bc4129c      11:27.9  ...         NaN             3.6
3  c8cacb82      46:27.9  ...         NaN             1.0
4  0bcf3f46      02:27.9  ...         NaN             1.5

[5 rows x 21 columns]
Traceback (most recent call last):
  File "C:\Users\LENOVO\Desktop\python1\Lib\site-packages\pandas\core\indexes\base.py", line 3805, in get_loc
    return self._engine.get_loc(casted_key)
  File "index.pyx", line 167, in pandas._libs.index.IndexEngine.get_loc
  File "index.pyx", line 196, in pandas._libs.index.IndexEngine.get_loc
  File "pandas\\_libs\\hashtable_class_helper.pxi", line 7081, in pandas._libs.hashtable.PyObjectHashTable.get_item
  File "pandas\\_libs\\hashtable_class_helper.pxi", line 7089, in pandas._libs.hashtable.PyObjectHashTable.get_item
KeyError: 0

The above exception was the direct cause of the following exception:

Traceback (most recent call last):
  File "C:/Users/LENOVO/Desktop/PYTHON FINAL PROJECT.py", line 72, in <module>
    plot.bar(completion['Pickup Location'], completion[0], color='blue')
  File "C:\Users\LENOVO\Desktop\python1\Lib\site-packages\pandas\core\frame.py", line 4102, in __getitem__
    indexer = self.columns.get_loc(key)
  File "C:\Users\LENOVO\Desktop\python1\Lib\site-packages\pandas\core\indexes\base.py", line 3812, in get_loc
    raise KeyError(key) from err
KeyError: 0

========== RESTART: C:/Users/LENOVO/Desktop/PYTHON FINAL PROJECT.py =========
    Ride ID Request Time  ... Canceled By Customer Rating
0  79efd31e      43:27.9  ...      Driver             0.0
1  75ee4cc8      27:27.9  ...      Driver             0.0
2  4bc4129c      11:27.9  ...         NaN             3.6
3  c8cacb82      46:27.9  ...         NaN             1.0
4  0bcf3f46      02:27.9  ...         NaN             1.5

[5 rows x 21 columns]

========== RESTART: C:/Users/LENOVO/Desktop/PYTHON FINAL PROJECT.py =========
    Ride ID Request Time  ... Canceled By Customer Rating
0  79efd31e      43:27.9  ...      Driver             0.0
1  75ee4cc8      27:27.9  ...      Driver             0.0
2  4bc4129c      11:27.9  ...         NaN             3.6
3  c8cacb82      46:27.9  ...         NaN             1.0
4  0bcf3f46      02:27.9  ...         NaN             1.5

[5 rows x 21 columns]
Traceback (most recent call last):
  File "C:\Users\LENOVO\Desktop\python1\Lib\site-packages\pandas\core\indexes\base.py", line 3805, in get_loc
    return self._engine.get_loc(casted_key)
  File "index.pyx", line 167, in pandas._libs.index.IndexEngine.get_loc
  File "index.pyx", line 196, in pandas._libs.index.IndexEngine.get_loc
  File "pandas\\_libs\\hashtable_class_helper.pxi", line 7081, in pandas._libs.hashtable.PyObjectHashTable.get_item
  File "pandas\\_libs\\hashtable_class_helper.pxi", line 7089, in pandas._libs.hashtable.PyObjectHashTable.get_item
KeyError: 0

The above exception was the direct cause of the following exception:

Traceback (most recent call last):
  File "C:/Users/LENOVO/Desktop/PYTHON FINAL PROJECT.py", line 72, in <module>
    plot.bar(completion['Pickup Location'], completion[0], color='blue')
  File "C:\Users\LENOVO\Desktop\python1\Lib\site-packages\pandas\core\frame.py", line 4102, in __getitem__
    indexer = self.columns.get_loc(key)
  File "C:\Users\LENOVO\Desktop\python1\Lib\site-packages\pandas\core\indexes\base.py", line 3812, in get_loc
    raise KeyError(key) from err
KeyError: 0

========== RESTART: C:/Users/LENOVO/Desktop/PYTHON FINAL PROJECT.py =========
    Ride ID Request Time  ... Canceled By Customer Rating
0  79efd31e      43:27.9  ...      Driver             0.0
1  75ee4cc8      27:27.9  ...      Driver             0.0
2  4bc4129c      11:27.9  ...         NaN             3.6
3  c8cacb82      46:27.9  ...         NaN             1.0
4  0bcf3f46      02:27.9  ...         NaN             1.5

[5 rows x 21 columns]

========== RESTART: C:/Users/LENOVO/Desktop/PYTHON FINAL PROJECT.py =========
    Ride ID Request Time  ... Canceled By Customer Rating
0  79efd31e      43:27.9  ...      Driver             0.0
1  75ee4cc8      27:27.9  ...      Driver             0.0
2  4bc4129c      11:27.9  ...         NaN             3.6
3  c8cacb82      46:27.9  ...         NaN             1.0
4  0bcf3f46      02:27.9  ...         NaN             1.5

[5 rows x 21 columns]

========== RESTART: C:/Users/LENOVO/Desktop/PYTHON FINAL PROJECT.py =========
    Ride ID Request Time  ... Canceled By Customer Rating
0  79efd31e      43:27.9  ...      Driver             0.0
1  75ee4cc8      27:27.9  ...      Driver             0.0
2  4bc4129c      11:27.9  ...         NaN             3.6
3  c8cacb82      46:27.9  ...         NaN             1.0
4  0bcf3f46      02:27.9  ...         NaN             1.5

[5 rows x 21 columns]

========== RESTART: C:/Users/LENOVO/Desktop/PYTHON FINAL PROJECT.py =========
    Ride ID Request Time  ... Canceled By Customer Rating
0  79efd31e      43:27.9  ...      Driver             0.0
1  75ee4cc8      27:27.9  ...      Driver             0.0
2  4bc4129c      11:27.9  ...         NaN             3.6
3  c8cacb82      46:27.9  ...         NaN             1.0
4  0bcf3f46      02:27.9  ...         NaN             1.5

[5 rows x 21 columns]
Traceback (most recent call last):
  File "C:\Users\LENOVO\Desktop\python1\Lib\site-packages\pandas\core\indexes\base.py", line 3805, in get_loc
    return self._engine.get_loc(casted_key)
  File "index.pyx", line 167, in pandas._libs.index.IndexEngine.get_loc
  File "index.pyx", line 196, in pandas._libs.index.IndexEngine.get_loc
  File "pandas\\_libs\\hashtable_class_helper.pxi", line 7081, in pandas._libs.hashtable.PyObjectHashTable.get_item
  File "pandas\\_libs\\hashtable_class_helper.pxi", line 7089, in pandas._libs.hashtable.PyObjectHashTable.get_item
KeyError: 'Time'

The above exception was the direct cause of the following exception:

Traceback (most recent call last):
  File "C:/Users/LENOVO/Desktop/PYTHON FINAL PROJECT.py", line 144, in <module>
    df['Time'] = pd.to_datetime(df['Time'])
  File "C:\Users\LENOVO\Desktop\python1\Lib\site-packages\pandas\core\frame.py", line 4102, in __getitem__
    indexer = self.columns.get_loc(key)
  File "C:\Users\LENOVO\Desktop\python1\Lib\site-packages\pandas\core\indexes\base.py", line 3812, in get_loc
    raise KeyError(key) from err
KeyError: 'Time'

========== RESTART: C:/Users/LENOVO/Desktop/PYTHON FINAL PROJECT.py =========
    Ride ID Request Time  ... Canceled By Customer Rating
0  79efd31e      43:27.9  ...      Driver             0.0
1  75ee4cc8      27:27.9  ...      Driver             0.0
2  4bc4129c      11:27.9  ...         NaN             3.6
3  c8cacb82      46:27.9  ...         NaN             1.0
4  0bcf3f46      02:27.9  ...         NaN             1.5

[5 rows x 21 columns]
Error creating moving trend line: No 'Time' column found in dataset.

========== RESTART: C:/Users/LENOVO/Desktop/PYTHON FINAL PROJECT.py =========
    Ride ID Request Time  ... Canceled By Customer Rating
0  79efd31e      43:27.9  ...      Driver             0.0
1  75ee4cc8      27:27.9  ...      Driver             0.0
2  4bc4129c      11:27.9  ...         NaN             3.6
3  c8cacb82      46:27.9  ...         NaN             1.0
4  0bcf3f46      02:27.9  ...         NaN             1.5

[5 rows x 21 columns]
Error creating moving trend line: No 'Requested Time' column found in dataset.

========== RESTART: C:/Users/LENOVO/Desktop/PYTHON FINAL PROJECT.py =========
    Ride ID Request Time  ... Canceled By Customer Rating
0  79efd31e      43:27.9  ...      Driver             0.0
1  75ee4cc8      27:27.9  ...      Driver             0.0
2  4bc4129c      11:27.9  ...         NaN             3.6
3  c8cacb82      46:27.9  ...         NaN             1.0
4  0bcf3f46      02:27.9  ...         NaN             1.5

[5 rows x 21 columns]

Warning (from warnings module):
  File "C:/Users/LENOVO/Desktop/PYTHON FINAL PROJECT.py", line 165
    df['Request Time'] = pd.to_datetime(df['Request Time'], errors='coerce')
UserWarning: Could not infer format, so each element will be parsed individually, falling back to `dateutil`. To ensure parsing is consistent and as-expected, please specify a format.
Error creating moving trend line: ['Requested Time']

========== RESTART: C:/Users/LENOVO/Desktop/PYTHON FINAL PROJECT.py =========
Traceback (most recent call last):
  File "C:/Users/LENOVO/Desktop/PYTHON FINAL PROJECT.py", line 9, in <module>
    df = pd.read_csv(file_path)
  File "C:\Users\LENOVO\Desktop\python1\Lib\site-packages\pandas\io\parsers\readers.py", line 1026, in read_csv
    return _read(filepath_or_buffer, kwds)
  File "C:\Users\LENOVO\Desktop\python1\Lib\site-packages\pandas\io\parsers\readers.py", line 620, in _read
    parser = TextFileReader(filepath_or_buffer, **kwds)
  File "C:\Users\LENOVO\Desktop\python1\Lib\site-packages\pandas\io\parsers\readers.py", line 1620, in __init__
    self._engine = self._make_engine(f, self.engine)
  File "C:\Users\LENOVO\Desktop\python1\Lib\site-packages\pandas\io\parsers\readers.py", line 1880, in _make_engine
    self.handles = get_handle(
  File "C:\Users\LENOVO\Desktop\python1\Lib\site-packages\pandas\io\common.py", line 873, in get_handle
    handle = open(
FileNotFoundError: [Errno 2] No such file or directory: '/mnt/data/rapido_lyft_ride_requests.csv'

========== RESTART: C:/Users/LENOVO/Desktop/PYTHON FINAL PROJECT.py =========
Traceback (most recent call last):
  File "C:\Users\LENOVO\Desktop\python1\Lib\site-packages\pandas\compat\_optional.py", line 135, in import_optional_dependency
    module = importlib.import_module(name)
  File "C:\Users\LENOVO\Desktop\python1\Lib\importlib\__init__.py", line 88, in import_module
    return _bootstrap._gcd_import(name[level:], package, level)
  File "<frozen importlib._bootstrap>", line 1387, in _gcd_import
  File "<frozen importlib._bootstrap>", line 1360, in _find_and_load
  File "<frozen importlib._bootstrap>", line 1324, in _find_and_load_unlocked
ModuleNotFoundError: No module named 'fsspec'

During handling of the above exception, another exception occurred:

Traceback (most recent call last):
  File "C:/Users/LENOVO/Desktop/PYTHON FINAL PROJECT.py", line 9, in <module>
    df = pd.read_csv(file_path)
  File "C:\Users\LENOVO\Desktop\python1\Lib\site-packages\pandas\io\parsers\readers.py", line 1026, in read_csv
    return _read(filepath_or_buffer, kwds)
  File "C:\Users\LENOVO\Desktop\python1\Lib\site-packages\pandas\io\parsers\readers.py", line 620, in _read
    parser = TextFileReader(filepath_or_buffer, **kwds)
  File "C:\Users\LENOVO\Desktop\python1\Lib\site-packages\pandas\io\parsers\readers.py", line 1620, in __init__
    self._engine = self._make_engine(f, self.engine)
  File "C:\Users\LENOVO\Desktop\python1\Lib\site-packages\pandas\io\parsers\readers.py", line 1880, in _make_engine
    self.handles = get_handle(
  File "C:\Users\LENOVO\Desktop\python1\Lib\site-packages\pandas\io\common.py", line 728, in get_handle
    ioargs = _get_filepath_or_buffer(
  File "C:\Users\LENOVO\Desktop\python1\Lib\site-packages\pandas\io\common.py", line 409, in _get_filepath_or_buffer
    fsspec = import_optional_dependency("fsspec")
  File "C:\Users\LENOVO\Desktop\python1\Lib\site-packages\pandas\compat\_optional.py", line 138, in import_optional_dependency
    raise ImportError(msg)
ImportError: Missing optional dependency 'fsspec'.  Use pip or conda to install fsspec.

========== RESTART: C:/Users/LENOVO/Desktop/PYTHON FINAL PROJECT.py =========

========== RESTART: C:/Users/LENOVO/Desktop/PYTHON FINAL PROJECT.py =========
    Ride ID Request Time  ... Canceled By Customer Rating
0  79efd31e      43:27.9  ...      Driver             0.0
1  75ee4cc8      27:27.9  ...      Driver             0.0
2  4bc4129c      11:27.9  ...         NaN             3.6
3  c8cacb82      46:27.9  ...         NaN             1.0
4  0bcf3f46      02:27.9  ...         NaN             1.5

[5 rows x 21 columns]
Traceback (most recent call last):
  File "C:/Users/LENOVO/Desktop/PYTHON FINAL PROJECT.py", line 112, in <module>
    sns.heatmap(corr, annot=True, cmap='coolwarm')
NameError: name 'sns' is not defined

========== RESTART: C:/Users/LENOVO/Desktop/PYTHON FINAL PROJECT.py =========

Initial Data Preview:
    Ride ID Request Time  ... Canceled By Customer Rating
0  79efd31e      43:27.9  ...      Driver             0.0
1  75ee4cc8      27:27.9  ...      Driver             0.0
2  4bc4129c      11:27.9  ...         NaN             3.6
3  c8cacb82      46:27.9  ...         NaN             1.0
4  0bcf3f46      02:27.9  ...         NaN             1.5

[5 rows x 21 columns]
==================================================

1. Average Fare Difference by Ride Type:
  Ride Type  Fare Difference
0      Auto        23.676653
1      Bike        23.381895
2       Car        23.534919
==================================================

2. Average Time Difference by Ride Type:
  Ride Type  Time Difference
0      Auto         2.100932
1      Bike         2.255988
2       Car         2.367733
==================================================

3. Distance vs Actual Fare (sample data):
   Distance (km)  Actual Fare
0           7.59  1401.476817
1          20.80   887.555431
2          16.09   124.516756
3          17.72   539.452013
4          17.10   278.093403
==================================================

4. Number of Rides by Ride Type:
  Ride Type  Count
0       Car    688
1      Bike    668
2      Auto    644
==================================================

5. Average Ride Time by Traffic Condition:
  Traffic Condition  Actual Time (mins)
0              High           26.689291
1               Low           28.034646
2            Medium           27.170940
==================================================

========== RESTART: C:/Users/LENOVO/Desktop/PYTHON FINAL PROJECT.py =========

Initial Data Preview:
    Ride ID Request Time  ... Canceled By Customer Rating
0  79efd31e      43:27.9  ...      Driver             0.0
1  75ee4cc8      27:27.9  ...      Driver             0.0
2  4bc4129c      11:27.9  ...         NaN             3.6
3  c8cacb82      46:27.9  ...         NaN             1.0
4  0bcf3f46      02:27.9  ...         NaN             1.5

[5 rows x 21 columns]
==================================================

1. Average Fare Difference by Ride Type:
  Ride Type  Fare Difference
0      Auto        23.676653
1      Bike        23.381895
2       Car        23.534919
==================================================

2. Average Time Difference by Ride Type:
  Ride Type  Time Difference
0      Auto         2.100932
1      Bike         2.255988
2       Car         2.367733
==================================================

3. Distance vs Actual Fare (sample data):
   Distance (km)  Actual Fare
0           7.59  1401.476817
1          20.80   887.555431
2          16.09   124.516756
3          17.72   539.452013
4          17.10   278.093403
==================================================

4. Number of Rides by Ride Type:
  Ride Type  Count
0       Car    688
1      Bike    668
2      Auto    644
==================================================

5. Average Ride Time by Traffic Condition:
  Traffic Condition  Actual Time (mins)
0              High           26.689291
1               Low           28.034646
2            Medium           27.170940
==================================================

6. Average Fare by Traffic Condition:
  Traffic Condition  Actual Fare
0              High   821.219451
1               Low   801.811687
2            Medium   806.954028
==================================================

7. Cancellation Reasons:
  Cancellation Reason  Count
0                 NaN    928
1  High Surge Pricing    283
2       Traffic Delay    278
3  Driver Unavailable    276
4    Customer No-show    235
==================================================

8. Preferred Payment Methods:
     Payment Method  Count
0  Cash on Delivery    413
1        Debit Card    402
2            Wallet    400
3               UPI    399
4       Credit Card    386
==================================================

9. Payment Failure Rate by Method:
     Payment Method  Failure %
0  Cash on Delivery  32.445521
1       Credit Card  37.564767
2        Debit Card  33.830846
3               UPI  32.080201
4            Wallet  36.750000
==================================================

10. Average Distance by Ride Type:
  Ride Type  Distance (km)
0      Auto      12.817609
1      Bike      12.885808
2       Car      13.134520
==================================================

11. Correlation Matrix between Distance, Time, and Fare:
                    Distance (km)  Actual Time (mins)  Actual Fare
Distance (km)            1.000000           -0.001560     0.022722
Actual Time (mins)      -0.001560            1.000000    -0.017376
Actual Fare              0.022722           -0.017376     1.000000
==================================================

12. Surge Pricing Impact by Traffic Condition:
  Traffic Condition  Fare Difference
0              High        23.528923
1               Low        23.207687
2            Medium        23.820993
==================================================

13. Fare per km by Ride Type:
  Ride Type  Fare per km
0      Auto   108.518734
1      Bike   106.127172
2       Car   102.352606
==================================================

14. Average Delay % by Traffic Condition:
  Traffic Condition    Delay %
0              High  11.191063
1               Low  15.176904
2            Medium  13.413882
==================================================

15. Completion Rate by Ride Type:
  Ride Type  Completion %
0      Auto     32.142857
1      Bike     35.628743
2       Car     34.738372
==================================================
>>> 
========== RESTART: C:/Users/LENOVO/Desktop/PYTHON FINAL PROJECT.py =========
    Ride ID Request Time  ... Canceled By Customer Rating
0  79efd31e      43:27.9  ...      Driver             0.0
1  75ee4cc8      27:27.9  ...      Driver             0.0
2  4bc4129c      11:27.9  ...         NaN             3.6
3  c8cacb82      46:27.9  ...         NaN             1.0
4  0bcf3f46      02:27.9  ...         NaN             1.5

[5 rows x 21 columns]
